<sdf version='1.10'>
  <world name='empty'>
    <physics name='1ms' type='ignored'>
      <max_step_size>0.001</max_step_size>
      <real_time_factor>1</real_time_factor>
      <real_time_update_rate>1000</real_time_update_rate>
    </physics>
    <plugin name='gz::sim::systems::Physics' filename='gz-sim-physics-system'/>
    <plugin name='gz::sim::systems::UserCommands' filename='gz-sim-user-commands-system'/>
    <plugin name='gz::sim::systems::SceneBroadcaster' filename='gz-sim-scene-broadcaster-system'/>
    <plugin name='gz::sim::systems::Contact' filename='gz-sim-contact-system'/>
    <gravity>0 0 -9.8000000000000007</gravity>
    <magnetic_field>5.5644999999999998e-06 2.2875799999999999e-05 -4.2388400000000002e-05</magnetic_field>
    <atmosphere type='adiabatic'/>
    <scene>
      <ambient>0.400000006 0.400000006 0.400000006 1</ambient>
      <background>0.699999988 0.699999988 0.699999988 1</background>
      <shadows>true</shadows>
    </scene>
    <model name='ground_plane'>
      <static>true</static>
      <link name='link'>
        <collision name='collision'>
          <geometry>
            <plane>
              <normal>0 0 1</normal>
              <size>100 100</size>
            </plane>
          </geometry>
          <surface>
            <friction>
              <ode/>
            </friction>
            <bounce/>
            <contact/>
          </surface>
        </collision>
        <visual name='visual'>
          <geometry>
            <plane>
              <normal>0 0 1</normal>
              <size>100 100</size>
            </plane>
          </geometry>
          <material>
            <ambient>0.800000012 0.800000012 0.800000012 1</ambient>
            <diffuse>0.800000012 0.800000012 0.800000012 1</diffuse>
            <specular>0.800000012 0.800000012 0.800000012 1</specular>
          </material>
        </visual>
        <pose>0 0 0 0 0 0</pose>
        <inertial>
          <pose>0 0 0 0 0 0</pose>
          <mass>1</mass>
          <inertia>
            <ixx>1</ixx>
            <ixy>0</ixy>
            <ixz>0</ixz>
            <iyy>1</iyy>
            <iyz>0</iyz>
            <izz>1</izz>
          </inertia>
        </inertial>
        <enable_wind>false</enable_wind>
      </link>
      <pose>0 0 0 0 0 0</pose>
      <self_collide>false</self_collide>
    </model>
    <model name='quadro'>
      <link name='base_footprint'>
        <inertial>
          <pose>0.002014251623993647 -6.7222455352735337e-05 0.006140018879082788 0 0 0</pose>
          <mass>4.2080601054111124</mass>
          <inertia>
            <ixx>0.01688751556455392</ixx>
            <ixy>0.00024765145258077569</ixy>
            <ixz>3.111691130067051e-05</ixz>
            <iyy>0.017533454770217529</iyy>
            <iyz>5.3522431139551828e-05</iyz>
            <izz>0.026878444924164122</izz>
          </inertia>
        </inertial>
        <collision name='base_footprint_fixed_joint_lump__base_link_collision'>
          <pose>0 0 0 0 0 0</pose>
          <geometry>
            <mesh>
              <scale>0.001 0.001 0.001</scale>
              <uri>file://<urdf-string>/model://quadro_description/meshes/base_link.stl</uri>
            </mesh>
          </geometry>
        </collision>
        <collision name='base_footprint_fixed_joint_lump__lidar_1_collision_1'>
          <pose>0 0 0 0 0 0</pose>
          <geometry>
            <mesh>
              <scale>0.001 0.001 0.001</scale>
              <uri>file://<urdf-string>/model://quadro_description/meshes/lidar_1.stl</uri>
            </mesh>
          </geometry>
          <surface>
            <contact>
              <ode/>
            </contact>
            <friction>
              <ode/>
            </friction>
          </surface>
        </collision>
        <visual name='base_footprint_fixed_joint_lump__base_link_visual'>
          <pose>0 0 0 0 0 0</pose>
          <geometry>
            <mesh>
              <scale>0.001 0.001 0.001</scale>
              <uri>file://<urdf-string>/model://quadro_description/meshes/base_link.stl</uri>
            </mesh>
          </geometry>
        </visual>
        <visual name='base_footprint_fixed_joint_lump__lidar_1_visual_1'>
          <pose>0 0 0 0 0 0</pose>
          <geometry>
            <mesh>
              <scale>0.001 0.001 0.001</scale>
              <uri>file://<urdf-string>/model://quadro_description/meshes/lidar_1.stl</uri>
            </mesh>
          </geometry>
        </visual>
        <sensor name='imu_sensor' type='imu'>
          <pose>0 0 0.01 0 0 0</pose>
          <topic>imu</topic>
          <update_rate>100</update_rate>
          <enable_metrics>false</enable_metrics>
          <imu>
            <orientation_reference_frame>
              <localization>CUSTOM</localization>
              <custom_rpy>0 0 0</custom_rpy>
              <grav_dir_x>1 0 0</grav_dir_x>
            </orientation_reference_frame>
            <angular_velocity>
              <x>
                <noise type='gaussian'>
                  <mean>0</mean>
                  <stddev>0.00020000000000000001</stddev>
                  <bias_mean>7.5000000000000002e-06</bias_mean>
                  <bias_stddev>7.9999999999999996e-07</bias_stddev>
                  <dynamic_bias_stddev>0</dynamic_bias_stddev>
                  <dynamic_bias_correlation_time>0</dynamic_bias_correlation_time>
                  <precision>0</precision>
                </noise>
              </x>
              <y>
                <noise type='gaussian'>
                  <mean>0</mean>
                  <stddev>0.00020000000000000001</stddev>
                  <bias_mean>7.5000000000000002e-06</bias_mean>
                  <bias_stddev>7.9999999999999996e-07</bias_stddev>
                  <dynamic_bias_stddev>0</dynamic_bias_stddev>
                  <dynamic_bias_correlation_time>0</dynamic_bias_correlation_time>
                  <precision>0</precision>
                </noise>
              </y>
              <z>
                <noise type='gaussian'>
                  <mean>0</mean>
                  <stddev>0.00020000000000000001</stddev>
                  <bias_mean>7.5000000000000002e-06</bias_mean>
                  <bias_stddev>7.9999999999999996e-07</bias_stddev>
                  <dynamic_bias_stddev>0</dynamic_bias_stddev>
                  <dynamic_bias_correlation_time>0</dynamic_bias_correlation_time>
                  <precision>0</precision>
                </noise>
              </z>
            </angular_velocity>
            <linear_acceleration>
              <x>
                <noise type='gaussian'>
                  <mean>0</mean>
                  <stddev>0.017000000000000001</stddev>
                  <bias_mean>0.10000000000000001</bias_mean>
                  <bias_stddev>0.001</bias_stddev>
                  <dynamic_bias_stddev>0</dynamic_bias_stddev>
                  <dynamic_bias_correlation_time>0</dynamic_bias_correlation_time>
                  <precision>0</precision>
                </noise>
              </x>
              <y>
                <noise type='gaussian'>
                  <mean>0</mean>
                  <stddev>0.017000000000000001</stddev>
                  <bias_mean>0.10000000000000001</bias_mean>
                  <bias_stddev>0.001</bias_stddev>
                  <dynamic_bias_stddev>0</dynamic_bias_stddev>
                  <dynamic_bias_correlation_time>0</dynamic_bias_correlation_time>
                  <precision>0</precision>
                </noise>
              </y>
              <z>
                <noise type='gaussian'>
                  <mean>0</mean>
                  <stddev>0.017000000000000001</stddev>
                  <bias_mean>0.10000000000000001</bias_mean>
                  <bias_stddev>0.001</bias_stddev>
                  <dynamic_bias_stddev>0</dynamic_bias_stddev>
                  <dynamic_bias_correlation_time>0</dynamic_bias_correlation_time>
                  <precision>0</precision>
                </noise>
              </z>
            </linear_acceleration>
            <enable_orientation>true</enable_orientation>
          </imu>
        </sensor>
        <sensor name='gpu_lidar' type='gpu_lidar'>
          <pose>-0.002098 -0.00083799999999999999 0.056952999999999997 0 0 0</pose>
          <topic>scan</topic>
          <update_rate>10</update_rate>
          <enable_metrics>false</enable_metrics>
          <lidar>
            <scan>
              <horizontal>
                <samples>720</samples>
                <resolution>1</resolution>
                <min_angle>-3.1459000000000001</min_angle>
                <max_angle>3.1459000000000001</max_angle>
              </horizontal>
              <vertical>
                <samples>1</samples>
                <min_angle>0</min_angle>
                <max_angle>0</max_angle>
                <resolution>1</resolution>
              </vertical>
            </scan>
            <range>
              <min>0.050000000000000003</min>
              <max>10</max>
              <resolution>0.01</resolution>
            </range>
            <noise>
              <type>gaussian</type>
              <mean>0</mean>
              <stddev>0.01</stddev>
            </noise>
            <visibility_mask>4294967295</visibility_mask>
          </lidar>
        </sensor>
        <pose>0 0 0 0 0 0</pose>
        <enable_wind>false</enable_wind>
      </link>
      <joint name='back_left_joint' type='revolute'>
        <pose>0 0 0 0 0 0</pose>
        <parent>base_footprint</parent>
        <child>back_left_wheel_1</child>
        <axis>
          <xyz>0 1 0</xyz>
          <limit>
            <lower>-inf</lower>
            <upper>inf</upper>
            <effort>inf</effort>
            <velocity>inf</velocity>
            <stiffness>100000000</stiffness>
            <dissipation>1</dissipation>
          </limit>
          <dynamics>
            <spring_reference>0</spring_reference>
            <spring_stiffness>0</spring_stiffness>
            <damping>0</damping>
            <friction>0</friction>
          </dynamics>
        </axis>
      </joint>
      <link name='back_left_wheel_1'>
        <pose>-0.090227999805208736 0.10026200169006752 -0.0084659986633316489 -3.1415926009201902 -0.1502618918641539 3.1415926457050958</pose>
        <inertial>
          <pose>5.8871043318031717e-08 0.01769182578117812 -3.0699335159742319e-07 0 0 0</pose>
          <mass>0.32258590654626068</mass>
          <inertia>
            <ixx>0.00013999999999999999</ixx>
            <ixy>0</ixy>
            <ixz>0</ixz>
            <iyy>0.000243</iyy>
            <iyz>0</iyz>
            <izz>0.00013999999999999999</izz>
          </inertia>
        </inertial>
        <collision name='back_left_wheel_1_collision'>
          <pose>0.090228000000000003 -0.100262 0.0084659999999999996 0 0 0</pose>
          <geometry>
            <mesh>
              <scale>0.001 0.001 0.001</scale>
              <uri>file://<urdf-string>/model://quadro_description/meshes/back_left_wheel_1.stl</uri>
            </mesh>
          </geometry>
        </collision>
        <visual name='back_left_wheel_1_visual'>
          <pose>0.090228000000000003 -0.100262 0.0084659999999999996 0 0 0</pose>
          <geometry>
            <mesh>
              <scale>0.001 0.001 0.001</scale>
              <uri>file://<urdf-string>/model://quadro_description/meshes/back_left_wheel_1.stl</uri>
            </mesh>
          </geometry>
        </visual>
        <enable_wind>false</enable_wind>
      </link>
      <joint name='back_right_joint' type='revolute'>
        <pose>0 0 0 0 0 0</pose>
        <parent>base_footprint</parent>
        <child>back_right_wheel_1</child>
        <axis>
          <xyz>0 1 0</xyz>
          <limit>
            <lower>-inf</lower>
            <upper>inf</upper>
            <effort>inf</effort>
            <velocity>inf</velocity>
            <stiffness>100000000</stiffness>
            <dissipation>1</dissipation>
          </limit>
          <dynamics>
            <spring_reference>0</spring_reference>
            <spring_stiffness>0</spring_stiffness>
            <damping>0</damping>
            <friction>0</friction>
          </dynamics>
        </axis>
      </joint>
      <link name='back_right_wheel_1'>
        <pose>-0.090227999254945596 -0.10193799353493158 -0.0084659546070958644 -3.1415924471502521 -0.26546046449036337 3.1415925994288258</pose>
        <inertial>
          <pose>5.887104327639836e-08 -0.017692571809081691 -3.0699092147014329e-07 0 0 0</pose>
          <mass>0.32258590654625968</mass>
          <inertia>
            <ixx>0.00013999999999999999</ixx>
            <ixy>0</ixy>
            <ixz>0</ixz>
            <iyy>0.000243</iyy>
            <iyz>0</iyz>
            <izz>0.00013999999999999999</izz>
          </inertia>
        </inertial>
        <collision name='back_right_wheel_1_collision'>
          <pose>0.090228000000000003 0.101938 0.0084659999999999996 0 0 0</pose>
          <geometry>
            <mesh>
              <scale>0.001 0.001 0.001</scale>
              <uri>file://<urdf-string>/model://quadro_description/meshes/back_right_wheel__1.stl</uri>
            </mesh>
          </geometry>
        </collision>
        <visual name='back_right_wheel_1_visual'>
          <pose>0.090228000000000003 0.101938 0.0084659999999999996 0 0 0</pose>
          <geometry>
            <mesh>
              <scale>0.001 0.001 0.001</scale>
              <uri>file://<urdf-string>/model://quadro_description/meshes/back_right_wheel__1.stl</uri>
            </mesh>
          </geometry>
        </visual>
        <enable_wind>false</enable_wind>
      </link>
      <joint name='front_left_joint' type='revolute'>
        <pose>0 0 0 0 0 0</pose>
        <parent>base_footprint</parent>
        <child>front_left_wheel_1</child>
        <axis>
          <xyz>0 1 0</xyz>
          <limit>
            <lower>-inf</lower>
            <upper>inf</upper>
            <effort>inf</effort>
            <velocity>inf</velocity>
            <stiffness>100000000</stiffness>
            <dissipation>1</dissipation>
          </limit>
          <dynamics>
            <spring_reference>0</spring_reference>
            <spring_stiffness>0</spring_stiffness>
            <damping>0</damping>
            <friction>0</friction>
          </dynamics>
        </axis>
      </joint>
      <link name='front_left_wheel_1'>
        <pose>0.087472000194791233 0.10026200169002984 -0.0084659997299160392 -3.1415926009201902 -0.15026190456115468 3.1415926457050949</pose>
        <inertial>
          <pose>5.8871041416774788e-08 0.017691825781178189 -3.0699335063812122e-07 0 0 0</pose>
          <mass>0.3225859065462604</mass>
          <inertia>
            <ixx>0.00013999999999999999</ixx>
            <ixy>0</ixy>
            <ixz>0</ixz>
            <iyy>0.000243</iyy>
            <iyz>0</iyz>
            <izz>0.00013999999999999999</izz>
          </inertia>
        </inertial>
        <collision name='front_left_wheel_1_collision'>
          <pose>-0.087471999999999994 -0.100262 0.0084659999999999996 0 0 0</pose>
          <geometry>
            <mesh>
              <scale>0.001 0.001 0.001</scale>
              <uri>file://<urdf-string>/model://quadro_description/meshes/front_left_wheel_1.stl</uri>
            </mesh>
          </geometry>
        </collision>
        <visual name='front_left_wheel_1_visual'>
          <pose>-0.087471999999999994 -0.100262 0.0084659999999999996 0 0 0</pose>
          <geometry>
            <mesh>
              <scale>0.001 0.001 0.001</scale>
              <uri>file://<urdf-string>/model://quadro_description/meshes/front_left_wheel_1.stl</uri>
            </mesh>
          </geometry>
        </visual>
        <enable_wind>false</enable_wind>
      </link>
      <joint name='front_right_joint' type='revolute'>
        <pose>0 0 0 0 0 0</pose>
        <parent>base_footprint</parent>
        <child>front_right_wheel_1</child>
        <axis>
          <xyz>0 1 0</xyz>
          <limit>
            <lower>-inf</lower>
            <upper>inf</upper>
            <effort>inf</effort>
            <velocity>inf</velocity>
            <stiffness>100000000</stiffness>
            <dissipation>1</dissipation>
          </limit>
          <dynamics>
            <spring_reference>0</spring_reference>
            <spring_stiffness>0</spring_stiffness>
            <damping>0</damping>
            <friction>0</friction>
          </dynamics>
        </axis>
      </joint>
      <link name='front_right_wheel_1'>
        <pose>0.087472000745054346 -0.10193799353507525 -0.0084659586875519069 -3.1415924471502499 -0.26546049801854427 3.1415925994288187</pose>
        <inertial>
          <pose>5.8871045066632988e-08 -0.017692571809081781 -3.0699092052992321e-07 0 0 0</pose>
          <mass>0.32258590654625968</mass>
          <inertia>
            <ixx>0.00013999999999999999</ixx>
            <ixy>0</ixy>
            <ixz>0</ixz>
            <iyy>0.000243</iyy>
            <iyz>0</iyz>
            <izz>0.00013999999999999999</izz>
          </inertia>
        </inertial>
        <collision name='front_right_wheel_1_collision'>
          <pose>-0.087471999999999994 0.101938 0.0084659999999999996 0 0 0</pose>
          <geometry>
            <mesh>
              <scale>0.001 0.001 0.001</scale>
              <uri>file://<urdf-string>/model://quadro_description/meshes/front_right_wheel_1.stl</uri>
            </mesh>
          </geometry>
        </collision>
        <visual name='front_right_wheel_1_visual'>
          <pose>-0.087471999999999994 0.101938 0.0084659999999999996 0 0 0</pose>
          <geometry>
            <mesh>
              <scale>0.001 0.001 0.001</scale>
              <uri>file://<urdf-string>/model://quadro_description/meshes/front_right_wheel_1.stl</uri>
            </mesh>
          </geometry>
        </visual>
        <enable_wind>false</enable_wind>
      </link>
      <plugin name='gz::sim::systems::Sensors' filename='gz-sim-sensors-system'>
        <render_engine>ogre2</render_engine>
      </plugin>
      <plugin name='gz::sim::systems::DiffDrive' filename='gz-sim-diff-drive-system'>
        <left_joint>front_left_joint</left_joint>
        <left_joint>back_left_joint</left_joint>
        <right_joint>front_right_joint</right_joint>
        <right_joint>back_right_joint</right_joint>
        <wheelbase>0.25</wheelbase>
        <wheel_separation>0.265</wheel_separation>
        <wheel_radius>0.0325</wheel_radius>
        <topic>cmd_vel</topic>
        <frame_id>odom</frame_id>
        <child_frame_id>base_footprint</child_frame_id>
      </plugin>
      <plugin name='gz::sim::systems::JointStatePublisher' filename='gz-sim-joint-state-publisher-system'>
        <topic>joint_states</topic>
      </plugin>
      <plugin name='gz::sim::systems::Imu' filename='gz-sim-imu-system'/>
      <frame name='imu_joint' attached_to='base_link'>
        <pose>0 0 0.01 0 0 0</pose>
      </frame>
      <frame name='imu_link' attached_to='imu_joint'>
        <pose>0 0 0 0 0 0</pose>
      </frame>
      <frame name='lidar_joint' attached_to='base_link'>
        <pose>-0.002098 -0.00083799999999999999 0.056952999999999997 0 0 0</pose>
      </frame>
      <frame name='lidar_1' attached_to='lidar_joint'>
        <pose>0 0 0 0 0 0</pose>
      </frame>
      <frame name='base_footprint_joint' attached_to='base_footprint'>
        <pose>0 0 0 0 0 0</pose>
      </frame>
      <frame name='base_link' attached_to='base_footprint_joint'>
        <pose>0 0 0 0 0 0</pose>
      </frame>
      <pose>-0.011171633753436147 0.002636444408469565 0.040915428458995713 3.2884689986902458e-05 -2.0000687176802445e-07 -0.015773840730090416</pose>
      <static>false</static>
      <self_collide>false</self_collide>
    </model>
    <model name='box'>
      <pose>1.5957181792516071 -0.029027513183827958 0.49999999990199806 6.2287739151293738e-22 9.3279666454713669e-22 -3.6315533669320137e-22</pose>
      <link name='box_link'>
        <inertial>
          <inertia>
            <ixx>0.16666</ixx>
            <ixy>0</ixy>
            <ixz>0</ixz>
            <iyy>0.16666</iyy>
            <iyz>0</iyz>
            <izz>0.16666</izz>
          </inertia>
          <mass>1</mass>
          <pose>0 0 0 0 0 0</pose>
        </inertial>
        <collision name='box_collision'>
          <geometry>
            <box>
              <size>1 1 1</size>
            </box>
          </geometry>
          <surface>
            <friction>
              <ode/>
            </friction>
            <bounce/>
            <contact/>
          </surface>
        </collision>
        <visual name='box_visual'>
          <geometry>
            <box>
              <size>1 1 1</size>
            </box>
          </geometry>
          <material>
            <ambient>0.300000012 0.300000012 0.300000012 1</ambient>
            <diffuse>0.699999988 0.699999988 0.699999988 1</diffuse>
            <specular>1 1 1 1</specular>
          </material>
        </visual>
        <pose>0 0 0 0 0 0</pose>
        <enable_wind>false</enable_wind>
      </link>
      <static>false</static>
      <self_collide>false</self_collide>
    </model>
    <model name='box_0'>
      <pose>-1.1759708411637979 1.8239874620861147 0.49999999990199806 3.0311822190606552e-21 3.0334240186237451e-21 3.1588773509749865e-22</pose>
      <link name='box_link'>
        <inertial>
          <inertia>
            <ixx>0.16666</ixx>
            <ixy>0</ixy>
            <ixz>0</ixz>
            <iyy>0.16666</iyy>
            <iyz>0</iyz>
            <izz>0.16666</izz>
          </inertia>
          <mass>1</mass>
          <pose>0 0 0 0 0 0</pose>
        </inertial>
        <collision name='box_collision'>
          <geometry>
            <box>
              <size>1 1 1</size>
            </box>
          </geometry>
          <surface>
            <friction>
              <ode/>
            </friction>
            <bounce/>
            <contact/>
          </surface>
        </collision>
        <visual name='box_visual'>
          <geometry>
            <box>
              <size>1 1 1</size>
            </box>
          </geometry>
          <material>
            <ambient>0.300000012 0.300000012 0.300000012 1</ambient>
            <diffuse>0.699999988 0.699999988 0.699999988 1</diffuse>
            <specular>1 1 1 1</specular>
          </material>
        </visual>
        <pose>0 0 0 0 0 0</pose>
        <enable_wind>false</enable_wind>
      </link>
      <static>false</static>
      <self_collide>false</self_collide>
    </model>
    <model name='cylinder'>
      <pose>-0.43176884477613098 -2.2865307283625977 0.49999942638036005 3.50117640419101e-19 2.4761090546689108e-19 -1.6295259478073628e-21</pose>
      <link name='cylinder_link'>
        <inertial>
          <inertia>
            <ixx>0.14580000000000001</ixx>
            <ixy>0</ixy>
            <ixz>0</ixz>
            <iyy>0.14580000000000001</iyy>
            <iyz>0</iyz>
            <izz>0.125</izz>
          </inertia>
          <mass>1</mass>
          <pose>0 0 0 0 0 0</pose>
        </inertial>
        <collision name='cylinder_collision'>
          <geometry>
            <cylinder>
              <radius>0.5</radius>
              <length>1</length>
            </cylinder>
          </geometry>
          <surface>
            <friction>
              <ode/>
            </friction>
            <bounce/>
            <contact/>
          </surface>
        </collision>
        <visual name='cylinder_visual'>
          <geometry>
            <cylinder>
              <radius>0.5</radius>
              <length>1</length>
            </cylinder>
          </geometry>
          <material>
            <ambient>0.300000012 0.300000012 0.300000012 1</ambient>
            <diffuse>0.699999988 0.699999988 0.699999988 1</diffuse>
            <specular>1 1 1 1</specular>
          </material>
        </visual>
        <pose>0 0 0 0 0 0</pose>
        <enable_wind>false</enable_wind>
      </link>
      <static>false</static>
      <self_collide>false</self_collide>
    </model>
    <light name='sun' type='directional'>
      <pose>0 0 10 0 0 0</pose>
      <cast_shadows>true</cast_shadows>
      <intensity>1</intensity>
      <direction>-0.5 0.10000000000000001 -0.90000000000000002</direction>
      <diffuse>0.800000012 0.800000012 0.800000012 1</diffuse>
      <specular>0.200000003 0.200000003 0.200000003 1</specular>
      <attenuation>
        <range>1000</range>
        <linear>0.01</linear>
        <constant>0.90000000000000002</constant>
        <quadratic>0.001</quadratic>
      </attenuation>
      <spot>
        <inner_angle>0</inner_angle>
        <outer_angle>0</outer_angle>
        <falloff>0</falloff>
      </spot>
    </light>
  </world>
</sdf>
