<?xml version="1.0" ?>
<robot name="quadro" xmlns:xacro="http://www.ros.org/wiki/xacro">

  <xacro:include filename="$(find quadro_description)/urdf/quadro_gazebo.xacro" />
  <!-- <xacro:include filename="$(find quadro_description)/urdf/lidar.xacro" /> -->
  <link name = "base_footprint">
  </link>
  <link name="base_link">
    <inertial>
      <origin xyz="0.00242982250627484 1.0699121762711983e-05 0.00012395016894092058" rpy="0 0 0"/>
      <mass value="3.8218753912768757"/>
      <inertia ixx="0.015284" iyy="0.015923" izz="0.026698" ixy="0.000249" iyz="3.4e-05" ixz="-7.3e-05"/>
    </inertial>
    <visual>
      <origin xyz="0 0 0" rpy="0 0 0"/>
      <geometry>
        <mesh filename="package://quadro_description/meshes/base_link.stl" scale="0.001 0.001 0.001"/>
      </geometry>
      
    </visual>
    <collision>
      <origin xyz="0 0 0" rpy="0 0 0"/>
      <geometry>
        <mesh filename="package://quadro_description/meshes/base_link.stl" scale="0.001 0.001 0.001"/>
      </geometry>
    </collision>
  </link>

  <link name="back_right_wheel_1">
    <inertial>
      <origin xyz="5.887104327639836e-08 -0.017692571809081695 -3.069909214701433e-07" rpy="0 0 0"/>
      <mass value="0.32258590654625974"/>
      <inertia ixx="0.00014" iyy="0.000243" izz="0.00014" ixy="-0.0" iyz="0.0" ixz="-0.0"/>
    </inertial>
    <visual>
      <origin xyz="0.090228 0.101938 0.008466" rpy="0 0 0"/>
      <geometry>
        <mesh filename="package://quadro_description/meshes/back_right_wheel__1.stl" scale="0.001 0.001 0.001"/>
      </geometry>
      
    </visual>
    <collision>
      <origin xyz="0.090228 0.101938 0.008466" rpy="0 0 0"/>
      <geometry>
        <mesh filename="package://quadro_description/meshes/back_right_wheel__1.stl" scale="0.001 0.001 0.001"/>
      </geometry>
    </collision>
  </link>

  <link name="front_right_wheel_1">
    <inertial>
      <origin xyz="5.887104506663299e-08 -0.017692571809081778 -3.0699092052992316e-07" rpy="0 0 0"/>
      <mass value="0.32258590654625974"/>
      <inertia ixx="0.00014" iyy="0.000243" izz="0.00014" ixy="-0.0" iyz="0.0" ixz="-0.0"/>
    </inertial>
    <visual>
      <origin xyz="-0.087472 0.101938 0.008466" rpy="0 0 0"/>
      <geometry>
        <mesh filename="package://quadro_description/meshes/front_right_wheel_1.stl" scale="0.001 0.001 0.001"/>
      </geometry>
      
    </visual>
    <collision>
      <origin xyz="-0.087472 0.101938 0.008466" rpy="0 0 0"/>
      <geometry>
        <mesh filename="package://quadro_description/meshes/front_right_wheel_1.stl" scale="0.001 0.001 0.001"/>
      </geometry>
    </collision>
  </link>

  <link name="front_left_wheel_1">
    <inertial>
      <origin xyz="5.8871041416774794e-08 0.017691825781178186 -3.0699335063812117e-07" rpy="0 0 0"/>
      <mass value="0.3225859065462604"/>
      <inertia ixx="0.00014" iyy="0.000243" izz="0.00014" ixy="0.0" iyz="0.0" ixz="0.0"/>
    </inertial>
    <visual>
      <origin xyz="-0.087472 -0.100262 0.008466" rpy="0 0 0"/>
      <geometry>
        <mesh filename="package://quadro_description/meshes/front_left_wheel_1.stl" scale="0.001 0.001 0.001"/>
      </geometry>
      
    </visual>
    <collision>
      <origin xyz="-0.087472 -0.100262 0.008466" rpy="0 0 0"/>
      <geometry>
        <mesh filename="package://quadro_description/meshes/front_left_wheel_1.stl" scale="0.001 0.001 0.001"/>
      </geometry>
    </collision>
  </link>

  <link name="back_left_wheel_1">
    <inertial>
      <origin xyz="5.8871043318031724e-08 0.017691825781178117 -3.0699335159742325e-07" rpy="0 0 0"/>
      <mass value="0.3225859065462607"/>
      <inertia ixx="0.00014" iyy="0.000243" izz="0.00014" ixy="0.0" iyz="0.0" ixz="0.0"/>
    </inertial>
    <visual>
      <origin xyz="0.090228 -0.100262 0.008466" rpy="0 0 0"/>
      <geometry>
        <mesh filename="package://quadro_description/meshes/back_left_wheel_1.stl" scale="0.001 0.001 0.001"/>
      </geometry>
      
    </visual>
    <collision>
      <origin xyz="0.090228 -0.100262 0.008466" rpy="0 0 0"/>
      <geometry>
        <mesh filename="package://quadro_description/meshes/back_left_wheel_1.stl" scale="0.001 0.001 0.001"/>
      </geometry>
    </collision>
  </link>

  <link name="lidar_1">
    <inertial>
        <origin xyz="-4.438561532929368e-07 -3.730139517365942e-07 0.008725017442976997" rpy="0 0 0"/>
        <mass value="0.3861847141342357"/>
        <inertia ixx="9.6e-05" iyy="9.6e-05" izz="0.000173" ixy="0.0" iyz="0.0" ixz="0.0"/>
    </inertial>
    <visual>
        <origin xyz="0.002098 0.000838 -0.056953" rpy="0 0 0"/>
        <geometry>
        <mesh filename="package://quadro_description/meshes/lidar_1.stl" scale="0.001 0.001 0.001"/>
        </geometry>      
    </visual>
    <collision>
        <origin xyz="0.002098 0.000838 -0.056953" rpy="0 0 0"/>
        <geometry>
        <mesh filename="package://quadro_description/meshes/lidar_1.stl" scale="0.001 0.001 0.001"/>
        </geometry>
    </collision>
  </link>

  <link name='imu_link'>
    <visual name="imu_link_visual">
      <geometry>
        <box><size>
          0.1 0.1 0.1
        </size></box>
      </geometry>
    </visual>

    <collision name="imu_link_collision">
      <geometry>
        <box><size>
          0.1 0.1 0.1
        </size></box>
      </geometry>
    </collision>

    <!-- <xacro:box_inertia m="0.1" w="0.1" d="0.1" h="0.1"/> -->
  </link>

  <joint name="lidar_joint" type="fixed">
    <origin xyz="-0.002098 -0.000838 0.056953" rpy="0 0 0"/>
    <parent link="base_link"/>
    <child link="lidar_1"/>
  </joint>

  <joint name = "base_footprint_joint" type = "fixed">
    <origin xyz = "0 0 0" rpy = "0 0 0"/>
    <parent link = "base_footprint"/>
    <child link = "base_link"/>
  </joint>

  <joint name="back_right_joint" type="continuous">
    <origin xyz="-0.090228 -0.101938 -0.008466" rpy="0 0 0"/>
    <parent link="base_link"/>
    <child link="back_right_wheel_1"/>
    <axis xyz="-0.0 1.0 -0.0"/>
  </joint>

  <joint name="front_right_joint" type="continuous">
    <origin xyz="0.087472 -0.101938 -0.008466" rpy="0 0 0"/>
    <parent link="base_link"/>
    <child link="front_right_wheel_1"/>
    <axis xyz="-0.0 1.0 0.0"/>
  </joint>

  <joint name="front_left_joint" type="continuous">
    <origin xyz="0.087472 0.100262 -0.008466" rpy="0 0 0"/>
    <parent link="base_link"/>
    <child link="front_left_wheel_1"/>
    <axis xyz="0.0 1.0 -0.0"/>
  </joint>

  <joint name="back_left_joint" type="continuous">
    <origin xyz="-0.090228 0.100262 -0.008466" rpy="0 0 0"/>
    <parent link="base_link"/>
    <child link="back_left_wheel_1"/>
    <axis xyz="0.0 1.0 0.0"/>
  </joint>

  <joint name='imu_joint' type='fixed'>
    <parent link = "base_link"/>
    <child link = "imu_link"/>
    <origin xyz="0.0 0.0 0.01" rpy="0 0 0"/>
  </joint>

</robot>
